<? xml version = "1.0" ?>
<robot name= "daVinci" >
<%
	BASE_WIDTH = 1.5
	BASE_LENGTH = BASE_WIDTH
	BASE_HEIGHT = 0.2
	BASE_MASS = 400.0

	SUPPORT_HEIGHT = 2.0
	SUPPORT_RADIUS = 0.15
	SUPPORT_MASS = 100.0

	SETUP_LENGTH = 1.0
	SETUP_RADIUS = 0.1
	SETUP_MASS = 10.0

	HINGE_LENGTH = 3 * SETUP_RADIUS
	HINGE_RADIUS = SETUP_RADIUS

	BASE_X_POS = 0
	BASE_Y_POS = 0
	BASE_Z_POS = BASE_HEIGHT / 2

	SUPPORT_X_POS = BASE_X_POS
	SUPPORT_Y_POS = BASE_Y_POS
	SUPPORT_Z_POS = BASE_Z_POS + (SUPPORT_HEIGHT / 2)
%>
	<joint name = "setup1_joint" type = "revolute" >
		<parent link= "base_link" />
    	<child link= "setup1_link" />
    	<origin xyz= "<%= SUPPORT_X_POS %> <%= SUPPORT_Y_POS %> <%= SUPPORT_Z_POS %>" rpy= "0 0 0" />
    	<axis xyz= "0 0 1" />
    	<limit effort= "100000" velocity= "1" lower = "-3.1416" upper = "3.1416" />
  	</joint>

  	<joint name = "setup2_joint" type = "revolute" >
		<parent link= "setup1_link" />
    	<child link= "setup2_link" />
    	<origin xyz= "<%= SUPPORT_X_POS %> <%= SETUP_LENGTH %> <%= SETUP_RADIUS %>" rpy= "0 0 0" />
    	<axis xyz= "0 0 1" />
    	<limit effort= "100000" velocity= "1" lower = "-1.5707" upper = "1.5707" />
  	</joint>

  	<joint name = "setup3_joint" type = "revolute" >
		<parent link= "setup2_link" />
    	<child link= "setup3_link" />
    	<origin xyz= "<%= SUPPORT_X_POS %> <%= SETUP_LENGTH %> <%= -SETUP_RADIUS %>" rpy= "0 0 0" />
    	<axis xyz= "0 0 1" />
    	<limit effort= "100000" velocity= "1" lower = "-1.5707" upper = "1.5707" />
  	</joint>

  	<joint name = "outer_yaw_joint" type = "revolute" >
		<parent link= "setup3_link" />
    	<child link= "outer_yaw_link" />
    	<origin xyz= "<%= SUPPORT_X_POS %> <%= (0.75 * SETUP_LENGTH) - 0.01 %> <%= 3 * SETUP_RADIUS %>" rpy= "0 0 0" />
    	<axis xyz= "0 1 0" />
    	<limit effort= "100000" velocity= "1" lower = "-1.0" upper = "1.0" />
  	</joint>

  	<joint name = "outer_pitch_back_joint" type = "revolute" >
		<parent link= "outer_yaw_link" />
    	<child link= "outer_pitch_back_link" />
    	<origin xyz= "0 0 0" rpy= "0 0 0" />
    	<axis xyz= "1 0 0" />
    	<limit effort= "100000" velocity= "1" lower = "-1.5707" upper = "1.5707" />
  	</joint>

   	<joint name = "outer_pitch_middle_joint" type = "revolute" >
		<parent link= "outer_pitch_back_link" />
    	<child link= "outer_pitch_middle_link" />
    	<origin xyz= "0 0 <%= ((SETUP_LENGTH / 2) - 0.02) / 4 %>" rpy= "0 0 0" />
    	<axis xyz= "1 0 0" />
    	<limit effort= "100000" velocity= "1" lower = "-1.5707" upper = "1.5707" />
  	</joint>

  	<joint name = "outer_pitch_front_joint" type = "revolute" >
		<parent link= "outer_pitch_middle_link" />
    	<child link= "outer_pitch_front_link" />
    	<origin xyz= "0 <%= SETUP_LENGTH / 2 %> 0" rpy= "0 0 0" />
    	<axis xyz= "1 0 0" />
    	<limit effort= "100000" velocity= "1" lower = "-1.5707" upper = "1.5707" />
  	</joint>

  	<joint name = "insertion_joint" type = "prismatic" >
  		<parent link = "outer_pitch_front_link" />
  		<child link = "insertion_link" />
  		<origin xyz = "0 0.0125 0" rpy = "0 0 0" />
  		<axis xyz = "0 0 1" />
  		<limit effort= "100000" velocity= "1" lower = "0" upper = "<%= SETUP_LENGTH / 3 %>" />
  	</joint>

  	<transmission name="setup1_joint_transmission">
    	<type> transmission_interface/SimpleTransmission </type>
    	<joint name="setup1_joint">
      		<hardwareInterface> hardware_interface/PositionJointInterface </hardwareInterface>
    	</joint>
    	<actuator name= "setup1_joint_motor">
      		<hardwareInterface> PositionJointInterface </hardwareInterface>
      		<mechanicalReduction> 1 </mechanicalReduction>
    	</actuator>
  	</transmission>

   	<transmission name="setup2_joint_transmission">
    	<type> transmission_interface/SimpleTransmission </type>
    	<joint name="setup2_joint">
      		<hardwareInterface> hardware_interface/PositionJointInterface </hardwareInterface>
    	</joint>
    	<actuator name= "setup2_joint_motor">
      		<hardwareInterface> PositionJointInterface </hardwareInterface>
      		<mechanicalReduction> 1 </mechanicalReduction>
    	</actuator>
  	</transmission>

   	<transmission name="setup3_joint_transmission">
    	<type> transmission_interface/SimpleTransmission </type>
    	<joint name="setup3_joint">
      		<hardwareInterface> hardware_interface/PositionJointInterface </hardwareInterface>
    	</joint>
    	<actuator name= "setup3_joint_motor">
      		<hardwareInterface> PositionJointInterface </hardwareInterface>
      		<mechanicalReduction> 1 </mechanicalReduction>
    	</actuator>
  	</transmission>

   	<transmission name="outer_yaw_joint_transmission">
    	<type> transmission_interface/SimpleTransmission </type>
    	<joint name="outer_yaw_joint">
      		<hardwareInterface> hardware_interface/PositionJointInterface </hardwareInterface>
    	</joint>
    	<actuator name= "outer_yaw_joint_motor">
      		<hardwareInterface> PositionJointInterface </hardwareInterface>
      		<mechanicalReduction> 1 </mechanicalReduction>
    	</actuator>
  	</transmission>

   	<transmission name="outer_pitch_back_joint_transmission">
    	<type> transmission_interface/SimpleTransmission </type>
    	<joint name="outer_pitch_back_joint">
      		<hardwareInterface> hardware_interface/PositionJointInterface </hardwareInterface>
    	</joint>
    	<actuator name= "outer_pitch_back_joint_motor">
      		<hardwareInterface> PositionJointInterface </hardwareInterface>
      		<mechanicalReduction> 1 </mechanicalReduction>
    	</actuator>
  	</transmission>

   	<transmission name="outer_pitch_middle_joint_transmission">
    	<type> transmission_interface/SimpleTransmission </type>
    	<joint name="outer_pitch_middle_joint">
      		<hardwareInterface> hardware_interface/PositionJointInterface </hardwareInterface>
    	</joint>
    	<actuator name= "outer_pitch_middle_joint_motor">
      		<hardwareInterface> PositionJointInterface </hardwareInterface>
      		<mechanicalReduction> 1 </mechanicalReduction>
    	</actuator>
  	</transmission>

   	<transmission name="outer_pitch_front_joint_transmission">
    	<type> transmission_interface/SimpleTransmission </type>
    	<joint name="outer_pitch_front_joint">
      		<hardwareInterface> hardware_interface/PositionJointInterface </hardwareInterface>
    	</joint>
    	<actuator name= "outer_pitch_front_joint_motor">
      		<hardwareInterface> PositionJointInterface </hardwareInterface>
      		<mechanicalReduction> 1 </mechanicalReduction>
    	</actuator>
  	</transmission>

  	<transmission name="insertion_box_joint_transmission">
    	<type> transmission_interface/SimpleTransmission </type>
    	<joint name="insertion_joint">
      		<hardwareInterface> hardware_interface/PositionJointInterface </hardwareInterface>
    	</joint>
    	<actuator name= "insertion_joint_motor">
      		<hardwareInterface> PositionJointInterface </hardwareInterface>
      		<mechanicalReduction> 1 </mechanicalReduction>
    	</actuator>
  	</transmission>

	<link name = "base_link" >

		<inertial>
			<mass value = "<%= BASE_MASS + SUPPORT_MASS %>" />
			<origin xyz = "<%= SUPPORT_X_POS %> <%= SUPPORT_Y_POS %> <%= SUPPORT_Z_POS %>" rpy = "0 0 0" />
			<inertia ixx = "100"
					 ixy = "100"
					 ixz = "100"
					 iyy = "100"
					 iyz = "100"
					 izz = "100" />
		</inertial>

		<visual name = "base_link_base_visual" >
			<origin xyz = "<%= BASE_X_POS %> <%= BASE_Y_POS %> <%= BASE_Z_POS %>" rpy = "0 0 0" />
			<geometry>
				<box size = "<%= BASE_LENGTH %> <%= BASE_WIDTH %> <%= BASE_HEIGHT %>" />
			</geometry>
		</visual>

		<collision name = "base_link_base_collision" >
			<origin xyz = "<%= BASE_X_POS %> <%= BASE_Y_POS %> <%= BASE_Z_POS %>" rpy = "0 0 0" />
			<geometry>
				<box size = "<%= BASE_LENGTH %> <%= BASE_WIDTH %> <%= BASE_HEIGHT %>" />
			</geometry>
		</collision>

		<visual name = "base_link_support_visual" >
			<origin xyz = "<%= SUPPORT_X_POS %> <%= SUPPORT_Y_POS %> <%= SUPPORT_Z_POS %>" rpy = "0 0 0" />
			<geometry>
				<cylinder radius = "<%= SUPPORT_RADIUS %>" length = "<%= SUPPORT_HEIGHT %>" />
			</geometry>
		</visual>

		<collision name = "base_link_support_collision" >
			<origin xyz = "<%= SUPPORT_X_POS %> <%= SUPPORT_Y_POS %> <%= SUPPORT_Z_POS %>" rpy = "0 0 0" />
			<geometry>
				<cylinder radius = "<%= SUPPORT_RADIUS %>" length = "<%= SUPPORT_HEIGHT %>" />
			</geometry>
		</collision>

	</link>

	<link name = "setup1_link" >

		<inertial>
			<mass value = "<%= SETUP_MASS %>" />
			<origin xyz = "0 <%= SETUP_LENGTH / 2 %> 0" rpy = "1.5707 0 0" />
			<inertia ixx = "0"
					 ixy = "0"
					 ixz = "0"
					 iyy = "0"
					 iyz = "0"
					 izz = "0" />
		</inertial>

		<visual name = "setup1_link_visual" >
			<origin xyz = "0 <%= SETUP_LENGTH / 2 %> 0" rpy = "1.5707 0 0" />
			<geometry>
				<cylinder radius = "<%= SETUP_RADIUS %>" length = "<%= SETUP_LENGTH %>" />
			</geometry>
		</visual>

		<collision name = "setup1_link_collision" >
			<origin xyz = "0 <%= SETUP_LENGTH / 2 %> 0" rpy = "1.5707 0 0" />
			<geometry>
				<cylinder radius = "<%= SETUP_RADIUS %>" length = "<%= SETUP_LENGTH %>" />
			</geometry>
		</collision>

	</link>

	<link name = "setup2_link" >

		<inertial>
			<mass value = "<%= SETUP_MASS %>" />
			<origin xyz = "0 <%= SETUP_LENGTH / 2 %> 0" rpy = "1.5707 0 0" />
			<inertia ixx = "0"
					 ixy = "0"
					 ixz = "0"
					 iyy = "0"
					 iyz = "0"
					 izz = "0" />
		</inertial>

		<visual name = "setup2_link_visual" >
			<origin xyz = "0 <%= SETUP_LENGTH / 2 %> 0" rpy = "1.5707 0 0" />
			<geometry>
				<cylinder radius = "<%= SETUP_RADIUS %>" length = "<%= SETUP_LENGTH %>" />
			</geometry>
		</visual>

		<collision name = "setup2_link_collision" >
			<origin xyz = "0 <%= SETUP_LENGTH / 2 %> 0" rpy = "1.5707 0 0" />
			<geometry>
				<cylinder radius = "<%= SETUP_RADIUS %>" length = "<%= SETUP_LENGTH %>" />
			</geometry>
		</collision>

		<visual name = "setup2_link_hinge_visual" >
			<origin xyz = "0 0 <%= -SETUP_RADIUS / 2 %>" rpy = "0 0 0" />
			<geometry>
				<cylinder radius = "<%= HINGE_RADIUS %>" length = "<%= HINGE_LENGTH %>" />
			</geometry>
		</visual>

		<collision name = "setup2_link_hinge_collision" >
			<origin xyz = "0 0 <%= -SETUP_RADIUS / 2 %>" rpy = "0 0 0" />
			<geometry>
				<cylinder radius = "<%= HINGE_RADIUS %>" length = "<%= HINGE_LENGTH %>" />
			</geometry>
		</collision>

	</link>

	<link name = "setup3_link" >

		<inertial>
			<mass value = "<%= SETUP_MASS %>" />
			<origin xyz = "0 <%= SETUP_LENGTH / 2 %> 0" rpy = "1.5707 0 0" />
			<inertia ixx = "0"
					 ixy = "0"
					 ixz = "0"
					 iyy = "0"
					 iyz = "0"
					 izz = "0" />
		</inertial>

		<visual name = "setup3_link_visual" >
			<origin xyz = "0 <%= SETUP_LENGTH / 2 %> 0" rpy = "1.5707 0 0" />
			<geometry>
				<cylinder radius = "<%= SETUP_RADIUS %>" length = "<%= SETUP_LENGTH %>" />
			</geometry>
		</visual>

		<collision name = "setup3_link_collision" >
			<origin xyz = "0 <%= SETUP_LENGTH / 2 %> 0" rpy = "1.5707 0 0" />
			<geometry>
				<cylinder radius = "<%= SETUP_RADIUS %>" length = "<%= SETUP_LENGTH %>" />
			</geometry>
		</collision>

		<visual name = "setup3_link_hinge_visual" >
			<origin xyz = "0 0 <%= SETUP_RADIUS / 2 %>" rpy = "0 0 0" />
			<geometry>
				<cylinder radius = "<%= HINGE_RADIUS %>" length = "<%= HINGE_LENGTH %>" />
			</geometry>
		</visual>

		<collision name = "setup3_link_hinge_collision" >
			<origin xyz = "0 0 <%= SETUP_RADIUS / 2 %>" rpy = "0 0 0" />
			<geometry>
				<cylinder radius = "<%= HINGE_RADIUS %>" length = "<%= HINGE_LENGTH %>" />
			</geometry>
		</collision>

		<visual name = "front_outer_yaw_link_support_visual" >
			<origin xyz = "0 <%= SETUP_LENGTH - 0.01 %> <%= 1.5 * SETUP_RADIUS %>" rpy = "0 0 0" />
			<geometry>
				<cylinder radius = "0.01" length = "<%= 3 * SETUP_RADIUS %>" />
			</geometry>
		</visual>

		<collision name = "front_outer_yaw_link_support_collision" >
			<origin xyz = "0 <%= SETUP_LENGTH - 0.01 %> <%= 1.5 * SETUP_RADIUS %>" rpy = "0 0 0" />
			<geometry>
				<cylinder radius = "0.01" length = "<%= 3 * SETUP_RADIUS %>" />
			</geometry>
		</collision>

		<visual name = "back_outer_yaw_link_support_visual" >
			<origin xyz = "0 <%= (SETUP_LENGTH / 2) - 0.01 %> <%= 1.5 * SETUP_RADIUS %>" rpy = "0 0 0" />
			<geometry>
				<cylinder radius = "0.01" length = "<%= 3 * SETUP_RADIUS %>" />
			</geometry>
		</visual>

		<collision name = "back_outer_yaw_link_support_collision" >
			<origin xyz = "0 <%= (SETUP_LENGTH / 2) - 0.01 %> <%= 1.5 * SETUP_RADIUS %>" rpy = "0 0 0" />
			<geometry>
				<cylinder radius = "0.01" length = "<%= 3 * SETUP_RADIUS %>" />
			</geometry>
		</collision>

	</link>

	<link name = "outer_yaw_link" >

		<inertial>
			<mass value = "1.0" />
			<origin xyz = "0 0 -0.05" rpy = "0 0 0" />
			<inertia ixx = "0"
					 ixy = "0"
					 ixz = "0"
					 iyy = "0"
					 iyz = "0"
					 izz = "0" />
		</inertial>

		<visual name = "outer_yaw_link_visual" >
			<origin xyz = "0 0 -0.05" rpy = "0 0 0" />
			<geometry>
				<box size = "0.2 <%= (SETUP_LENGTH / 2) - 0.02 %> 0.1" />
			</geometry>
		</visual>

		<collision name = "outer_yaw_link_collision" >
			<origin xyz = "0 0 -0.05" rpy = "0 0 0" />
			<geometry>
				<box size = "0.2 <%= (SETUP_LENGTH / 2) - 0.02 %> 0.1" />
			</geometry>
		</collision>

	</link>

	<link name = "outer_pitch_back_link" >

		<inertial>
			<mass value = "1.0" />
			<origin xyz = "0 0 <%= ((SETUP_LENGTH / 2) - 0.02) / 8 %>" rpy = "0 0 0" />
			<inertia ixx = "0"
					 ixy = "0"
					 ixz = "0"
					 iyy = "0"
					 iyz = "0"
					 izz = "0" />
		</inertial>

		<visual name = "outer_pitch_back_link_visual" >
			<origin xyz = "0 0 <%= ((SETUP_LENGTH / 2) - 0.02) / 8 %>" rpy = "0 0 0" />
			<geometry>
				<box size = "0.1 0.01 <%= ((SETUP_LENGTH / 2) - 0.02) / 4 %>" />
			</geometry>
		</visual>

		<collision name = "outer_pitch_back_link_collision" >
			<origin xyz = "0 0 <%= ((SETUP_LENGTH / 2) - 0.02) / 8 %>" rpy = "0 0 0" />
			<geometry>
				<box size = "0.1 0.01 <%= ((SETUP_LENGTH / 2) - 0.02) / 4 %>" />
			</geometry>
		</collision>

	</link>

	<link name = "outer_pitch_middle_link" >

		<inertial>
			<mass value = "1.0" />
			<origin xyz = "0 <%= SETUP_LENGTH / 4 %> 0" rpy = "0 0 0" />
			<inertia ixx = "0"
					 ixy = "0"
					 ixz = "0"
					 iyy = "0"
					 iyz = "0"
					 izz = "0" />
		</inertial>

		<visual name = "outer_pitch_middle_link_visual" >
			<origin xyz = "0 <%= SETUP_LENGTH / 4 %> 0" rpy = "0 0 0" />
			<geometry>
				<box size = "0.1 <%= SETUP_LENGTH / 2 %> 0.01" />
			</geometry>
		</visual>

		<collision name = "outer_pitch_middle_link_collision" >
			<origin xyz = "0 <%= SETUP_LENGTH / 4 %> 0" rpy = "0 0 0" />
			<geometry>
				<box size = "0.1 <%= SETUP_LENGTH / 2 %> 0.01" />
			</geometry>
		</collision>

	</link>

	<link name = "outer_pitch_front_link" >

		<inertial>
			<mass value = "1.0" />
			<origin xyz = "0 0 <%= 0.75 * (SETUP_LENGTH / 4) %>" rpy = "0 0 0" />
			<inertia ixx = "0"
					 ixy = "0"
					 ixz = "0"
					 iyy = "0"
					 iyz = "0"
					 izz = "0" />
		</inertial>

		<visual name = "outer_pitch_front_link_visual" >
			<origin xyz = "0 0 <%= 0.75 * (SETUP_LENGTH / 4) %>" rpy = "0 0 0" />
			<geometry>
				<box size = "0.1 0.01 <%= SETUP_LENGTH / 2 %>" />
			</geometry>
		</visual>

		<collision name = "outer_pitch_front_link_collision" >
			<origin xyz = "0 0 <%= 0.75 * (SETUP_LENGTH / 4) %>" rpy = "0 0 0" />
			<geometry>
				<box size = "0.1 0.01 <%= SETUP_LENGTH / 2 %>" />
			</geometry>
		</collision>

	</link>

	<link name = "insertion_link" >

		<inertial>
			<mass value = "0.0001" />
			<origin xyz = "0 0.0125 0" rpy = "0 0 0" />
			<inertia ixx = "0"
					 ixy = "0"
					 ixz = "0"
					 iyy = "0"
					 iyz = "0"
					 izz = "0" />
		</inertial>

		<visual name = "insertion_box_link_visual" >
			<origin xyz = "0 0.0125 0" rpy = "0 0 0" />
			<geometry>
				<box size = "0.075 0.025 0.1" />
			</geometry>
		</visual>

		<collision name = "insertion_box_link_collision" >
			<origin xyz = "0 0.0125 0" rpy = "0 0 0" />
			<geometry>
				<box size = "0.075 0.025 0.1" />
			</geometry>
		</collision>

		<visual name = "insertion_rod_link_visual" >
			<origin xyz = "0 0.0375 -0.25" rpy = "0 0 0" />
			<geometry>
				<cylinder length = "0.5" radius = "0.0125" />
			</geometry>
		</visual>

		<collision name = "insertion_rod_link_collision" >
			<origin xyz = "0 0.0375 -0.25" rpy = "0 0 0" />
			<geometry>
				<cylinder length = "0.5" radius = "0.0125" />
			</geometry>
		</collision>

	</link>

	<gazebo>

	  <static> false </static>

	  <plugin name="gazebo_ros_control" filename="libgazebo_ros_control.so">
	    <robotNamespace> /daVinci </robotNamespace>
	  </plugin>

	  <plugin name = "libroboticsgroup_gazebo_mimic_joint_plugin" filename = "libroboticsgroup_gazebo_mimic_joint_plugin.so">
	  	<robotNamespace> /daVinci </robotNamespace>
	  	<joint> outer_pitch_back_joint </joint>
	  	<mimicJoint> outer_pitch_middle_joint </mimicJoint>
	  	<multiplier> -1 </multiplier>
	  	<offset> 0 </offset>
	  </plugin>

	  <plugin name = "libroboticsgroup_gazebo_mimic_joint_plugin" filename = "libroboticsgroup_gazebo_mimic_joint_plugin.so">
	  	<robotNamespace> /daVinci </robotNamespace>
	  	<joint> outer_pitch_back_joint </joint>
	  	<mimicJoint> outer_pitch_front_joint </mimicJoint>
	  	<multiplier> 1 </multiplier>
	  	<offset> 0 </offset>
	  </plugin>
	  
	</gazebo>

</robot>

